Workbook

Sheet Master_104_Matches
A1: match_id | B1: match_date | C1: stage | D1: group | E1: team_a | F1: team_b | G1: fifa_rank_diff | H1: elo_rating_diff | I1: last5_avg_goals_scored_diff | J1: last5_avg_goals_conceded_diff | K1: last5_win_rate_diff | L1: last5_clean_sheet_rate_diff | M1: rest_days_diff | N1: last5_opponent_strength_diff | O1: team_a_goals | P1: team_b_goals | Q1: result_note | R1: goal_difference | S1: collection_status | T1: source_url
A2: 1 | B2: 46184 | C2: Group Stage | D2: A | E2: Mexico | F2: South Africa | J2: =X4_X6_Audit!J2 -> -0.6 | L2: =X4_X6_Audit!O2 -> 0.2 | M2: 2 | N2: -34 | O2: 2 | P2: 0 | R2: =O2-P2 -> 2 | S2: =IF(COUNTA(G2:N2)=0,"Not Started",IF(COUNTA(G2:N2)=8,"Complete","In Progress")) -> In Progress | T2: https://www.fifa.com/en/tournaments/mens/worldcup/canadamexicousa2026/articles/match-schedule-fixtures-results-teams-stadiums
A3: 2 | B3: 46184 | C3: Group Stage | D3: A | E3: Korea Republic | F3: Czechia | J3: =X4_X6_Audit!J3 -> -0.2 | L3: =X4_X6_Audit!O3 -> 0.4 | M3: 1 | N3: -23.6 | O3: 2 | P3: 1 | R3: =O3-P3 -> 1 | S3: =IF(COUNTA(G3:N3)=0,"Not Started",IF(COUNTA(G3:N3)=8,"Complete","In Progress")) -> In Progress | T3: https://www.fifa.com/en/tournaments/mens/worldcup/canadamexicousa2026/articles/match-schedule-fixtures-results-teams-stadiums
A4: 3 | B4: 46185 | C4: Group Stage | D4: B | E4: Canada | F4: Bosnia and Herzegovina | J4: =X4_X6_Audit!J4 -> -0.2 | L4: =X4_X6_Audit!O4 -> 0.4 | M4: 1 | N4: 30.4 | O4: 1 | P4: 1 | R4: =O4-P4 -> 0 | S4: =IF(COUNTA(G4:N4)=0,"Not Started",IF(COUNTA(G4:N4)=8,"Complete","In Progress")) -> In Progress | T4: https://www.fifa.com/en/tournaments/mens/worldcup/canadamexicousa2026/articles/match-schedule-fixtures-results-teams-stadiums
A5: 4 | B5: 46185 | C5: Group Stage | D5: D | E5: USA | F5: Paraguay | J5: =X4_X6_Audit!J5 -> 1.4 | L5: =X4_X6_Audit!O5 -> -0.4 | M5: -1 | N5: -32.2 | O5: 4 | P5: 1 | R5: =O5-P5 -> 3 | S5: =IF(COUNTA(G5:N5)=0,"Not Started",IF(COUNTA(G5:N5)=8,"Complete","In Progress")) -> In Progress | T5: https://www.fifa.com/en/tournaments/mens/worldcup/canadamexicousa2026/articles/match-schedule-fixtures-results-teams-stadiums
A6: 5 | B6: 46186 | C6: Group Stage | D6: C | E6: Haiti | F6: Scotland | J6: =X4_X6_Audit!J6 -> -0.2 | L6: =X4_X6_Audit!O6 -> 0.2 | M6: 1 | N6: 31.6 | O6: 0 | P6: 1 | R6: =O6-P6 -> -1 | S6: =IF(COUNTA(G6:N6)=0,"Not Started",IF(COUNTA(G6:N6)=8,"Complete","In Progress")) -> In Progress | T6: https://www.fifa.com/en/tournaments/mens/worldcup/canadamexicousa2026/articles/match-schedule-fixtures-results-teams-stadiums
A7: 6 | B7: 46186 | C7: Group Stage | D7: D | E7: Australia | F7: Türkiye | J7: =X4_X6_Audit!J7 -> 0.6 | L7: =X4_X6_Audit!O7 -> -0.4 | M7: 0 | N7: -14.4 | O7: 2 | P7: 0 | R7: =O7-P7 -> 2 | S7: =IF(COUNTA(G7:N7)=0,"Not Started",IF(COUNTA(G7:N7)=8,"Complete","In Progress")) -> In Progress | T7: https://www.fifa.com/en/tournaments/mens/worldcup/canadamexicousa2026/articles/match-schedule-fixtures-results-teams-stadiums
A8: 7 | B8: 46186 | C8: Group Stage | D8: C | E8: Brazil | F8: Morocco | J8: =X4_X6_Audit!J8 -> 0.8 | L8: =X4_X6_Audit!O8 -> -0.4 | M8: 1 | N8: -44.2 | O8: 1 | P8: 1 | R8: =O8-P8 -> 0 | S8: =IF(COUNTA(G8:N8)=0,"Not Started",IF(COUNTA(G8:N8)=8,"Complete","In Progress")) -> In Progress | T8: https://www.fifa.com/en/tournaments/mens/worldcup/canadamexicousa2026/articles/match-schedule-fixtures-results-teams-stadiums
A9: 8 | B9: 46186 | C9: Group Stage | D9: B | E9: Qatar | F9: Switzerland | J9: =X4_X6_Audit!J9 -> -0.2 | L9: =X4_X6_Audit!O9 -> 0 | M9: 0 | N9: 33.2 | O9: 1 | P9: 1 | R9: =O9-P9 -> 0 | S9: =IF(COUNTA(G9:N9)=0,"Not Started",IF(COUNTA(G9:N9)=8,"Complete","In Progress")) -> In Progress | T9: https://www.fifa.com/en/tournaments/mens/worldcup/canadamexicousa2026/articles/match-schedule-fixtures-results-teams-stadiums
A10: 9 | B10: 46187 | C10: Group Stage | D10: E | E10: Côte d'Ivoire | F10: Ecuador | J10: =X4_X6_Audit!J10 -> 0.2 | L10: =X4_X6_Audit!O10 -> 0.2 | M10: 3 | N10: -19.8 | O10: 1 | P10: 0 | R10: =O10-P10 -> 1 | S10: =IF(COUNTA(G10:N10)=0,"Not Started",IF(COUNTA(G10:N10)=8,"Complete","In Progress")) -> In Progress | T10: https://www.fifa.com/en/tournaments/mens/worldcup/canadamexicousa2026/articles/match-schedule-fixtures-results-teams-stadiums
A11: 10 | B11: 46187 | C11: Group Stage | D11: E | E11: Germany | F11: Curaçao | J11: =X4_X6_Audit!J11 -> -1.2 | L11: =X4_X6_Audit!O11 -> 0 | M11: 0 | N11: -39 | O11: 7 | P11: 1 | R11: =O11-P11 -> 6 | S11: =IF(COUNTA(G11:N11)=0,"Not Started",IF(COUNTA(G11:N11)=8,"Complete","In Progress")) -> In Progress | T11: https://www.fifa.com/en/tournaments/mens/worldcup/canadamexicousa2026/articles/match-schedule-fixtures-results-teams-stadiums
A12: 11 | B12: 46187 | C12: Group Stage | D12: F | E12: Netherlands | F12: Japan | J12: =X4_X6_Audit!J12 -> 0.8 | L12: =X4_X6_Audit!O12 -> -0.8 | M12: -8 | N12: 2.6 | O12: 2 | P12: 2 | R12: =O12-P12 -> 0 | S12: =IF(COUNTA(G12:N12)=0,"Not Started",IF(COUNTA(G12:N12)=8,"Complete","In Progress")) -> In Progress | T12: https://www.fifa.com/en/tournaments/mens/worldcup/canadamexicousa2026/articles/match-schedule-fixtures-results-teams-stadiums
A13: 12 | B13: 46187 | C13: Group Stage | D13: F | E13: Sweden | F13: Tunisia | J13: =X4_X6_Audit!J13 -> 0.4 | L13: =X4_X6_Audit!O13 -> -0.4 | M13: 2 | N13: -1 | O13: 5 | P13: 1 | R13: =O13-P13 -> 4 | S13: =IF(COUNTA(G13:N13)=0,"Not Started",IF(COUNTA(G13:N13)=8,"Complete","In Progress")) -> In Progress | T13: https://www.fifa.com/en/tournaments/mens/worldcup/canadamexicousa2026/articles/match-schedule-fixtures-results-teams-stadiums
... A73: 72 | B73: 46200 | C73: Group Stage | D73: K | E73: Congo DR | F73: Uzbekistan | J73: =X4_X6_Audit!J73 -> -1.6 | L73: =X4_X6_Audit!O73 -> 0.2 | M73: 0 | N73: 11.4 | O73: 3 | P73: 1 | R73: =O73-P73 -> 2 | S73: =IF(COUNTA(G73:N73)=0,"Not Started",IF(COUNTA(G73:N73)=8,"Complete","In Progress")) -> In Progress | T73: https://www.fifa.com/en/tournaments/mens/worldcup/canadamexicousa2026/articles/match-schedule-fixtures-results-teams-stadiums
A74: 73 | B74: 46201 | C74: Round of 32 | E74: South Africa | F74: Canada | J74: =X4_X6_Audit!J74 -> -0.2 | L74: =X4_X6_Audit!O74 -> 0.2 | M74: 0 | N74: 6.6 | O74: 0 | P74: 1 | R74: =O74-P74 -> -1 | S74: =IF(COUNTA(G74:N74)=0,"Not Started",IF(COUNTA(G74:N74)=8,"Complete","In Progress")) -> In Progress | T74: https://www.fifa.com/en/tournaments/mens/worldcup/2026/articles/knockout-stage-match-schedule-bracket
A75: 74 | B75: 46202 | C75: Round of 32 | E75: Germany | F75: Paraguay | J75: =X4_X6_Audit!J75 -> -0.2 | L75: =X4_X6_Audit!O75 -> -0.4 | M75: 0 | N75: 4.4 | O75: 1 | P75: 1 | Q75: PSO 3-4 | R75: =O75-P75 -> 0 | S75: =IF(COUNTA(G75:N75)=0,"Not Started",IF(COUNTA(G75:N75)=8,"Complete","In Progress")) -> In Progress | T75: https://www.fifa.com/en/tournaments/mens/worldcup/2026/articles/knockout-stage-match-schedule-bracket
A76: 75 | B76: 46202 | C76: Round of 32 | E76: Netherlands | F76: Morocco | J76: =X4_X6_Audit!J76 -> 0.4 | L76: =X4_X6_Audit!O76 -> -0.4 | M76: -1 | N76: -17.4 | O76: 1 | P76: 1 | Q76: PSO 2-3 | R76: =O76-P76 -> 0 | S76: =IF(COUNTA(G76:N76)=0,"Not Started",IF(COUNTA(G76:N76)=8,"Complete","In Progress")) -> In Progress | T76: https://www.fifa.com/en/tournaments/mens/worldcup/2026/articles/knockout-stage-match-schedule-bracket
A77: 76 | B77: 46202 | C77: Round of 32 | E77: Brazil | F77: Japan | J77: =X4_X6_Audit!J77 -> 0.2 | L77: =X4_X6_Audit!O77 -> -0.2 | M77: 1 | N77: 4.8 | O77: 2 | P77: 1 | R77: =O77-P77 -> 1 | S77: =IF(COUNTA(G77:N77)=0,"Not Started",IF(COUNTA(G77:N77)=8,"Complete","In Progress")) -> In Progress | T77: https://www.fifa.com/en/tournaments/mens/worldcup/2026/articles/knockout-stage-match-schedule-bracket
A78: 77 | B78: 46203 | C78: Round of 32 | E78: France | F78: Sweden | J78: =X4_X6_Audit!J78 -> -1.4 | L78: =X4_X6_Audit!O78 -> 0.2 | M78: -1 | N78: 11.6 | O78: 3 | P78: 0 | R78: =O78-P78 -> 3 | S78: =IF(COUNTA(G78:N78)=0,"Not Started",IF(COUNTA(G78:N78)=8,"Complete","In Progress")) -> In Progress | T78: https://www.fifa.com/en/tournaments/mens/worldcup/2026/articles/knockout-stage-match-schedule-bracket
A79: 78 | B79: 46203 | C79: Round of 32 | E79: Côte d'Ivoire | F79: Norway | J79: =X4_X6_Audit!J79 -> -1.2 | L79: =X4_X6_Audit!O79 -> 0.6 | M79: 1 | N79: 6.6 | O79: 1 | P79: 2 | R79: =O79-P79 -> -1 | S79: =IF(COUNTA(G79:N79)=0,"Not Started",IF(COUNTA(G79:N79)=8,"Complete","In Progress")) -> In Progress | T79: https://www.fifa.com/en/tournaments/mens/worldcup/2026/articles/knockout-stage-match-schedule-bracket
A80: 79 | B80: 46203 | C80: Round of 32 | E80: Mexico | F80: Ecuador | J80: =X4_X6_Audit!J80 -> -0.4 | L80: =X4_X6_Audit!O80 -> 0.4 | M80: 1 | N80: -18.2 | O80: 2 | P80: 0 | R80: =O80-P80 -> 2 | S80: =IF(COUNTA(G80:N80)=0,"Not Started",IF(COUNTA(G80:N80)=8,"Complete","In Progress")) -> In Progress | T80: https://www.fifa.com/en/tournaments/mens/worldcup/2026/articles/knockout-stage-match-schedule-bracket
A81: 80 | B81: 46204 | C81: Round of 32 | E81: England | F81: Congo DR | J81: =X4_X6_Audit!J81 -> -0.6 | L81: =X4_X6_Audit!O81 -> 0.6 | M81: 0 | N81: 22.4 | O81: 2 | P81: 1 | R81: =O81-P81 -> 1 | S81: =IF(COUNTA(G81:N81)=0,"Not Started",IF(COUNTA(G81:N81)=8,"Complete","In Progress")) -> In Progress | T81: https://www.fifa.com/en/tournaments/mens/worldcup/2026/articles/knockout-stage-match-schedule-bracket
A82: 81 | B82: 46204 | C82: Round of 32 | E82: USA | F82: Bosnia and Herzegovina | J82: =X4_X6_Audit!J82 -> 0.2 | L82: =X4_X6_Audit!O82 -> 0 | M82: -1 | N82: -18.2 | O82: 2 | P82: 0 | R82: =O82-P82 -> 2 | S82: =IF(COUNTA(G82:N82)=0,"Not Started",IF(COUNTA(G82:N82)=8,"Complete","In Progress")) -> In Progress | T82: https://www.fifa.com/en/tournaments/mens/worldcup/2026/articles/knockout-stage-match-schedule-bracket
A83: 82 | B83: 46204 | C83: Round of 32 | E83: Belgium | F83: Senegal | J83: =X4_X6_Audit!J83 -> -1.4 | L83: =X4_X6_Audit!O83 -> 0.2 | M83: 0 | N83: 4.2 | O83: 3 | P83: 2 | Q83: AET | R83: =O83-P83 -> 1 | S83: =IF(COUNTA(G83:N83)=0,"Not Started",IF(COUNTA(G83:N83)=8,"Complete","In Progress")) -> In Progress | T83: https://www.fifa.com/en/tournaments/mens/worldcup/2026/articles/knockout-stage-match-schedule-bracket
A84: 83 | B84: 46205 | C84: Round of 32 | E84: Portugal | F84: Croatia | J84: =X4_X6_Audit!J84 -> -1 | L84: =X4_X6_Audit!O84 -> 0.2 | M84: 0 | N84: 2.2 | O84: 2 | P84: 1 | R84: =O84-P84 -> 1 | S84: =IF(COUNTA(G84:N84)=0,"Not Started",IF(COUNTA(G84:N84)=8,"Complete","In Progress")) -> In Progress | T84: https://www.fifa.com/en/tournaments/mens/worldcup/2026/articles/knockout-stage-match-schedule-bracket
A85: 84 | B85: 46205 | C85: Round of 32 | E85: Spain | F85: Austria | J85: =X4_X6_Audit!J85 -> -0.8 | L85: =X4_X6_Audit!O85 -> 0.2 | M85: 1 | N85: 19.2 | O85: 3 | P85: 0 | R85: =O85-P85 -> 3 | S85: =IF(COUNTA(G85:N85)=0,"Not Started",IF(COUNTA(G85:N85)=8,"Complete","In Progress")) -> In Progress | T85: https://www.fifa.com/en/tournaments/mens/worldcup/2026/articles/knockout-stage-match-schedule-bracket
A86: 85 | B86: 46205 | C86: Round of 32 | E86: Switzerland | F86: Algeria | J86: =X4_X6_Audit!J86 -> -0.4 | L86: =X4_X6_Audit!O86 -> -0.4 | M86: 3 | N86: 13.8 | O86: 2 | P86: 0 | R86: =O86-P86 -> 2 | S86: =IF(COUNTA(G86:N86)=0,"Not Started",IF(COUNTA(G86:N86)=8,"Complete","In Progress")) -> In Progress | T86: https://www.fifa.com/en/tournaments/mens/worldcup/2026/articles/knockout-stage-match-schedule-bracket
A87: 86 | B87: 46206 | C87: Round of 32 | E87: Argentina | F87: Cabo Verde | J87: =X4_X6_Audit!J87 -> -0.8 | L87: =X4_X6_Audit!O87 -> 0.2 | M87: -1 | N87: -5.6 | O87: 3 | P87: 2 | Q87: AET | R87: =O87-P87 -> 1 | S87: =IF(COUNTA(G87:N87)=0,"Not Started",IF(COUNTA(G87:N87)=8,"Complete","In Progress")) -> In Progress | T87: https://www.fifa.com/en/tournaments/mens/worldcup/2026/articles/knockout-stage-match-schedule-bracket
A88: 87 | B88: 46206 | C88: Round of 32 | E88: Colombia | F88: Ghana | J88: =X4_X6_Audit!J88 -> -0.6 | L88: =X4_X6_Audit!O88 -> 0.2 | M88: 0 | N88: 22.8 | O88: 1 | P88: 0 | R88: =O88-P88 -> 1 | S88: =IF(COUNTA(G88:N88)=0,"Not Started",IF(COUNTA(G88:N88)=8,"Complete","In Progress")) -> In Progress | T88: https://www.fifa.com/en/tournaments/mens/worldcup/2026/articles/knockout-stage-match-schedule-bracket
A89: 88 | B89: 46206 | C89: Round of 32 | E89: Australia | F89: Egypt | J89: =X4_X6_Audit!J89 -> -0.2 | L89: =X4_X6_Audit!O89 -> 0.2 | M89: 1 | N89: -8.4 | O89: 1 | P89: 1 | Q89: PSO 2-4 | R89: =O89-P89 -> 0 | S89: =IF(COUNTA(G89:N89)=0,"Not Started",IF(COUNTA(G89:N89)=8,"Complete","In Progress")) -> In Progress | T89: https://www.fifa.com/en/tournaments/mens/worldcup/2026/articles/knockout-stage-match-schedule-bracket
A90: 89 | B90: 46207 | C90: Round of 16 | E90: Paraguay | F90: France | J90: =X4_X6_Audit!J90 -> 0.4 | L90: =X4_X6_Audit!O90 -> 0.2 | M90: 1 | N90: -0.8 | O90: 0 | P90: 1 | R90: =O90-P90 -> -1 | S90: =IF(COUNTA(G90:N90)=0,"Not Started",IF(COUNTA(G90:N90)=8,"Complete","In Progress")) -> In Progress | T90: https://www.fifa.com/en/tournaments/mens/worldcup/2026/articles/knockout-stage-match-schedule-bracket
A91: 90 | B91: 46207 | C91: Round of 16 | E91: Canada | F91: Morocco | J91: =X4_X6_Audit!J91 -> -0.2 | L91: =X4_X6_Audit!O91 -> 0.2 | M91: 1 | N91: 17.6 | O91: 0 | P91: 3 | R91: =O91-P91 -> -3 | S91: =IF(COUNTA(G91:N91)=0,"Not Started",IF(COUNTA(G91:N91)=8,"Complete","In Progress")) -> In Progress | T91: https://www.fifa.com/en/tournaments/mens/worldcup/2026/articles/knockout-stage-match-schedule-bracket
A92: 91 | B92: 46208 | C92: Round of 16 | E92: Brazil | F92: Norway | J92: =X4_X6_Audit!J92 -> -1.2 | L92: =X4_X6_Audit!O92 -> 0.4 | M92: 1 | N92: 12.6 | O92: 1 | P92: 2 | R92: =O92-P92 -> -1 | S92: =IF(COUNTA(G92:N92)=0,"Not Started",IF(COUNTA(G92:N92)=8,"Complete","In Progress")) -> In Progress | T92: https://www.fifa.com/en/tournaments/mens/worldcup/2026/articles/knockout-stage-match-schedule-bracket
A93: 92 | B93: 46208 | C93: Round of 16 | E93: Mexico | F93: England | J93: =X4_X6_Audit!J93 -> -0.4 | L93: =X4_X6_Audit!O93 -> 0.2 | M93: 1 | N93: -5.6 | O93: 2 | P93: 3 | R93: =O93-P93 -> -1 | S93: =IF(COUNTA(G93:N93)=0,"Not Started",IF(COUNTA(G93:N93)=8,"Complete","In Progress")) -> In Progress | T93: https://www.fifa.com/en/tournaments/mens/worldcup/2026/articles/knockout-stage-match-schedule-bracket
A94: 93 | B94: 46209 | C94: Round of 16 | E94: Portugal | F94: Spain | J94: =X4_X6_Audit!J94 -> 0.4 | L94: =X4_X6_Audit!O94 -> -0.4 | M94: 0 | N94: -15 | O94: 0 | P94: 1 | R94: =O94-P94 -> -1 | S94: =IF(COUNTA(G94:N94)=0,"Not Started",IF(COUNTA(G94:N94)=8,"Complete","In Progress")) -> In Progress | T94: https://www.fifa.com/en/tournaments/mens/worldcup/2026/articles/knockout-stage-match-schedule-bracket
A95: 94 | B95: 46209 | C95: Round of 16 | E95: USA | F95: Belgium | J95: =X4_X6_Audit!J95 -> 0.4 | L95: =X4_X6_Audit!O95 -> 0 | M95: 0 | N95: -5.8 | O95: 1 | P95: 4 | R95: =O95-P95 -> -3 | S95: =IF(COUNTA(G95:N95)=0,"Not Started",IF(COUNTA(G95:N95)=8,"Complete","In Progress")) -> In Progress | T95: https://www.fifa.com/en/tournaments/mens/worldcup/2026/articles/knockout-stage-match-schedule-bracket
A96: 95 | B96: 46210 | C96: Round of 16 | E96: Argentina | F96: Egypt | J96: =X4_X6_Audit!J96 -> -0.6 | L96: =X4_X6_Audit!O96 -> 0.6 | M96: 0 | N96: 22 | O96: 3 | P96: 2 | R96: =O96-P96 -> 1 | S96: =IF(COUNTA(G96:N96)=0,"Not Started",IF(COUNTA(G96:N96)=8,"Complete","In Progress")) -> In Progress | T96: https://www.fifa.com/en/tournaments/mens/worldcup/2026/articles/knockout-stage-match-schedule-bracket
A97: 96 | B97: 46210 | C97: Round of 16 | E97: Switzerland | F97: Colombia | J97: =X4_X6_Audit!J97 -> 0.6 | L97: =X4_X6_Audit!O97 -> -0.6 | M97: 1 | N97: -6.4 | O97: 0 | P97: 0 | Q97: PSO 4-3 | R97: =O97-P97 -> 0 | S97: =IF(COUNTA(G97:N97)=0,"Not Started",IF(COUNTA(G97:N97)=8,"Complete","In Progress")) -> In Progress | T97: https://www.fifa.com/en/tournaments/mens/worldcup/2026/articles/knockout-stage-match-schedule-bracket
A98: 97 | B98: 46212 | C98: Quarter-finals | E98: France | F98: Morocco | J98: =X4_X6_Audit!J98 -> -0.4 | L98: =X4_X6_Audit!O98 -> 0.2 | M98: 0 | N98: 2.6 | O98: 2 | P98: 0 | R98: =O98-P98 -> 2 | S98: =IF(COUNTA(G98:N98)=0,"Not Started",IF(COUNTA(G98:N98)=8,"Complete","In Progress")) -> In Progress | T98: https://www.fifa.com/en/tournaments/mens/worldcup/2026/articles/knockout-stage-match-schedule-bracket
A99: 98 | B99: 46213 | C99: Quarter-finals | E99: Spain | F99: Belgium | J99: =X4_X6_Audit!J99 -> -1 | L99: =X4_X6_Audit!O99 -> 0.8 | M99: 0 | N99: 1.4 | O99: 2 | P99: 1 | R99: =O99-P99 -> 1 | S99: =IF(COUNTA(G99:N99)=0,"Not Started",IF(COUNTA(G99:N99)=8,"Complete","In Progress")) -> In Progress | T99: https://www.fifa.com/en/tournaments/mens/worldcup/2026/articles/knockout-stage-match-schedule-bracket
...

Sheet Data_Rules
A1: Rule | B1: Agreed definition
A2: Team A / Team B | B2: Team A is the first-listed team in the FIFA match record; Team B is the second-listed team.
A3: Difference direction | B3: All eight explanatory variables use Team A value − Team B value.
A4: Previous five matches | B4: The five most recent senior international matches completed before kickoff of the match being predicted.
A5: No data leakage | B5: Do not use the current match or any match that occurred later.
A6: FIFA ranking | B6: Use the latest official FIFA ranking publication available before kickoff.
A7: Penalty shootouts | B7: Do not add penalty-shootout kicks to goals scored, goals conceded, or goal difference.
A8: Extra time | B8: Include goals scored during extra time in the final match score and goal difference.
A9: Win rate after PSO | B9: If a historical match is level after extra time and decided by penalties, treat it as a draw for win-rate calculation.
A10: Missing data | B10: The old xG and shots-on-target predictors were replaced. Do not substitute 0 for missing values in the eight current predictors; investigate or document missingness.
A11: match_id | B11: This is an internal project identifier assigned chronologically from 1 to 104; it is not intended to represent FIFA's official match number.
A12: Target | B12: goal_difference = team_a_goals − team_b_goals.
... A17: Target versus features | B17: Goal difference = Team A goals minus Team B goals. Goal difference and the two current-match goal columns are outcomes, not explanatory variables; exclude them from X.

Sheet X4_X6_Audit
A1: match_id | B1: team_a | C1: team_b | D1: Team A previous 5 (date opponent GF-GA) | E1: Team B previous 5 (date opponent GF-GA) | F1: A goals conceded (5) | G1: B goals conceded (5) | H1: A avg conceded | I1: B avg conceded | J1: X4 = A - B | K1: A clean sheets (of 5) | L1: B clean sheets (of 5) | M1: A clean-sheet rate | N1: B clean-sheet rate | O1: X6 = A - B
A2: 1 | B2: Mexico | C2: South Africa | D2: 2026-03-28 Portugal 0-0; 2026-03-31 Belgium 1-1; 2026-05-22 Ghana 2-0; 2026-05-30 Australia 1-0; 2026-06-04 Serbia 5-1 | E2: 2026-01-04 Cameroon 1-2; 2026-03-27 Panama 1-1; 2026-03-31 Panama 1-2; 2026-05-29 Nicaragua 0-0; 2026-06-06 Jamaica 1-0 | F2: 2 | G2: 5 | H2: =F2/5 -> 0.4 | I2: =G2/5 -> 1 | J2: =H2-I2 -> -0.6 | K2: 3 | L2: 2 | M2: =K2/5 -> 0.6 | N2: =L2/5 -> 0.4 | O2: =M2-N2 -> 0.2
A3: 2 | B3: Korea Republic | C3: Czechia | D3: 2025-11-18 Ghana 1-0; 2026-03-28 Ivory Coast 0-4; 2026-03-31 Austria 0-1; 2026-05-30 Trinidad and Tobago 5-0; 2026-06-03 El Salvador 1-0 | E3: 2025-11-17 Gibraltar 6-0; 2026-03-26 Republic of Ireland 2-2; 2026-03-31 Denmark 2-2; 2026-05-31 Kosovo 2-1; 2026-06-04 Guatemala 5-1 | F3: 5 | G3: 6 | H3: =F3/5 -> 1 | I3: =G3/5 -> 1.2 | J3: =H3-I3 -> -0.2 | K3: 3 | L3: 1 | M3: =K3/5 -> 0.6 | N3: =L3/5 -> 0.2 | O3: =M3-N3 -> 0.4
A4: 3 | B4: Canada | C4: Bosnia and Herzegovina | D4: 2025-11-18 Venezuela 2-0; 2026-03-28 Iceland 2-2; 2026-03-31 Tunisia 0-0; 2026-06-01 Uzbekistan 2-0; 2026-06-05 Republic of Ireland 1-1 | E4: 2025-11-18 Austria 1-1; 2026-03-26 Wales 1-1; 2026-03-31 Italy 1-1; 2026-05-29 North Macedonia 0-0; 2026-06-06 Panama 1-1 | F4: 3 | G4: 4 | H4: =F4/5 -> 0.6 | I4: =G4/5 -> 0.8 | J4: =H4-I4 -> -0.2 | K4: 3 | L4: 1 | M4: =K4/5 -> 0.6 | N4: =L4/5 -> 0.2 | O4: =M4-N4 -> 0.4
A5: 4 | B5: USA | C5: Paraguay | D5: 2025-11-18 Uruguay 5-1; 2026-03-28 Belgium 2-5; 2026-03-31 Portugal 0-2; 2026-05-31 Senegal 3-2; 2026-06-06 Germany 1-2 | E5: 2025-11-15 United States 1-2; 2025-11-18 Mexico 2-1; 2026-03-27 Greece 1-0; 2026-03-31 Morocco 1-2; 2026-06-05 Nicaragua 4-0 | F5: 12 | G5: 5 | H5: =F5/5 -> 2.4 | I5: =G5/5 -> 1 | J5: =H5-I5 -> 1.4 | K5: 0 | L5: 2 | M5: =K5/5 -> 0 | N5: =L5/5 -> 0.4 | O5: =M5-N5 -> -0.4
A6: 5 | B6: Haiti | C6: Scotland | D6: 2025-11-18 Nicaragua 2-0; 2026-03-28 Tunisia 0-1; 2026-03-31 Iceland 1-1; 2026-06-02 New Zealand 4-0; 2026-06-05 Peru 1-2 | E6: 2025-11-18 Denmark 4-2; 2026-03-28 Japan 0-1; 2026-03-31 Ivory Coast 0-1; 2026-05-30 Curaçao 4-1; 2026-06-06 Bolivia 4-0 | F6: 4 | G6: 5 | H6: =F6/5 -> 0.8 | I6: =G6/5 -> 1 | J6: =H6-I6 -> -0.2 | K6: 2 | L6: 1 | M6: =K6/5 -> 0.4 | N6: =L6/5 -> 0.2 | O6: =M6-N6 -> 0.2
A7: 6 | B7: Australia | C7: Türkiye | D7: 2025-11-18 Colombia 0-3; 2026-03-27 Cameroon 1-0; 2026-03-31 Curaçao 5-1; 2026-05-30 Mexico 0-1; 2026-06-06 Switzerland 1-1 | E7: 2025-11-18 Spain 2-2; 2026-03-26 Romania 1-0; 2026-03-31 Kosovo 1-0; 2026-06-01 North Macedonia 4-0; 2026-06-06 Venezuela 2-1 | F7: 6 | G7: 3 | H7: =F7/5 -> 1.2 | I7: =G7/5 -> 0.6 | J7: =H7-I7 -> 0.6 | K7: 1 | L7: 3 | M7: =K7/5 -> 0.2 | N7: =L7/5 -> 0.6 | O7: =M7-N7 -> -0.4
A8: 7 | B8: Brazil | C8: Morocco | D8: 2025-11-18 Tunisia 1-1; 2026-03-26 France 1-2; 2026-03-31 Croatia 3-1; 2026-05-31 Panama 6-2; 2026-06-06 Egypt 2-1 | E8: 2026-03-27 Ecuador 1-1; 2026-03-31 Paraguay 2-1; 2026-05-26 Burundi 5-0; 2026-06-02 Madagascar 4-0; 2026-06-07 Norway 1-1 | F8: 7 | G8: 3 | H8: =F8/5 -> 1.4 | I8: =G8/5 -> 0.6 | J8: =H8-I8 -> 0.8 | K8: 0 | L8: 2 | M8: =K8/5 -> 0 | N8: =L8/5 -> 0.4 | O8: =M8-N8 -> -0.4
A9: 8 | B9: Qatar | C9: Switzerland | D9: 2025-12-01 Palestine 0-1; 2025-12-04 Syria 1-1; 2025-12-07 Tunisia 0-3; 2026-05-28 Republic of Ireland 0-1; 2026-06-06 El Salvador 0-0 | E9: 2025-11-18 Kosovo 1-1; 2026-03-27 Germany 3-4; 2026-03-31 Norway 0-0; 2026-05-31 Jordan 4-1; 2026-06-06 Australia 1-1 | F9: 6 | G9: 7 | H9: =F9/5 -> 1.2 | I9: =G9/5 -> 1.4 | J9: =H9-I9 -> -0.2 | K9: 1 | L9: 1 | M9: =K9/5 -> 0.2 | N9: =L9/5 -> 0.2 | O9: =M9-N9 -> 0
A10: 9 | B10: Côte d'Ivoire | C10: Ecuador | D10: 2026-01-06 Burkina Faso 3-0; 2026-01-10 Egypt 2-3; 2026-03-28 South Korea 4-0; 2026-03-31 Scotland 1-0; 2026-06-04 France 2-1 | E10: 2025-11-18 New Zealand 2-0; 2026-03-27 Morocco 1-1; 2026-03-31 Netherlands 1-1; 2026-05-30 Saudi Arabia 2-1; 2026-06-07 Guatemala 3-0 | F10: 4 | G10: 3 | H10: =F10/5 -> 0.8 | I10: =G10/5 -> 0.6 | J10: =H10-I10 -> 0.2 | K10: 3 | L10: 2 | M10: =K10/5 -> 0.6 | N10: =L10/5 -> 0.4 | O10: =M10-N10 -> 0.2
A11: 10 | B11: Germany | C11: Curaçao | D11: 2025-11-17 Slovakia 6-0; 2026-03-27 Switzerland 4-3; 2026-03-30 Ghana 2-1; 2026-05-31 Finland 4-0; 2026-06-06 United States 2-1 | E11: 2025-11-18 Jamaica 0-0; 2026-03-27 China 0-2; 2026-03-31 Australia 1-5; 2026-05-30 Scotland 1-4; 2026-06-06 Aruba 4-0 | F11: 5 | G11: 11 | H11: =F11/5 -> 1 | I11: =G11/5 -> 2.2 | J11: =H11-I11 -> -1.2 | K11: 2 | L11: 2 | M11: =K11/5 -> 0.4 | N11: =L11/5 -> 0.4 | O11: =M11-N11 -> 0
A12: 11 | B12: Netherlands | C12: Japan | D12: 2025-11-17 Lithuania 4-0; 2026-03-27 Norway 2-1; 2026-03-31 Ecuador 1-1; 2026-06-03 Algeria 0-1; 2026-06-08 Uzbekistan 2-1 | E12: 2025-11-14 Ghana 2-0; 2025-11-18 Bolivia 3-0; 2026-03-28 Scotland 1-0; 2026-03-31 England 1-0; 2026-05-31 Iceland 1-0 | F12: 4 | G12: 0 | H12: =F12/5 -> 0.8 | I12: =G12/5 -> 0 | J12: =H12-I12 -> 0.8 | K12: 1 | L12: 5 | M12: =K12/5 -> 0.2 | N12: =L12/5 -> 1 | O12: =M12-N12 -> -0.8
A13: 12 | B13: Sweden | C13: Tunisia | D13: 2025-11-18 Slovenia 1-1; 2026-03-26 Ukraine 3-1; 2026-03-31 Poland 3-2; 2026-06-01 Norway 1-3; 2026-06-04 Greece 2-2 | E13: 2026-01-03 Mali 1-1; 2026-03-28 Haiti 1-0; 2026-03-31 Canada 0-0; 2026-06-01 Austria 0-1; 2026-06-06 Belgium 0-5 | F13: 9 | G13: 7 | H13: =F13/5 -> 1.8 | I13: =G13/5 -> 1.4 | J13: =H13-I13 -> 0.4 | K13: 0 | L13: 2 | M13: =K13/5 -> 0 | N13: =L13/5 -> 0.4 | O13: =M13-N13 -> -0.4
... A105: 104 | B105: Spain | C105: Argentina | D105: 2026-06-26 Uruguay 1-0; 2026-07-02 Austria 3-0; 2026-07-06 Portugal 1-0; 2026-07-10 Belgium 2-1; 2026-07-14 France 2-0 | E105: 2026-06-27 Jordan 3-1; 2026-07-03 Cape Verde 3-2; 2026-07-07 Egypt 3-2; 2026-07-11 Switzerland 3-1; 2026-07-15 England 2-1 | F105: 1 | G105: 7 | H105: =F105/5 -> 0.2 | I105: =G105/5 -> 1.4 | J105: =H105-I105 -> -1.2 | K105: 4 | L105: 0 | M105: =K105/5 -> 0.8 | N105: =L105/5 -> 0 | O105: =M105-N105 -> 0.8
A107: Method notes (X4 and X6 only):
A108: Source: martj42/international_results (github.com/martj42/international_results) - all senior men's internationals through Oct 2026; shootout goals excluded, extra-time goals included.
A109: Window: each team's 5 most recent completed matches strictly before kickoff date, any competition, current match excluded; tournament matches already played count for later rounds.
A110: X4 = avg goals conceded (A, prev 5) - avg goals conceded (B, prev 5). Negative favours Team A. X6 = clean-sheet rate (A) - clean-sheet rate (B); clean sheet = 0 goals conceded. Positive favours Team A.
A111: Master columns J and L link to this sheet (J = X4, L = X6). No other master columns were changed.
